2019-01-16 16:56:00,906 ERROR: Exception on /search [GET] [in C:\Users\asu7\.virtualenvs\microblog-PZe2x5ce\lib\site-packages\flask\app.py:1761]
Traceback (most recent call last):
  File "C:\Users\asu7\.virtualenvs\microblog-PZe2x5ce\lib\site-packages\flask\app.py", line 2292, in wsgi_app
    response = self.full_dispatch_request()
  File "C:\Users\asu7\.virtualenvs\microblog-PZe2x5ce\lib\site-packages\flask\app.py", line 1815, in full_dispatch_request
    rv = self.handle_user_exception(e)
  File "C:\Users\asu7\.virtualenvs\microblog-PZe2x5ce\lib\site-packages\flask\app.py", line 1718, in handle_user_exception
    reraise(exc_type, exc_value, tb)
  File "C:\Users\asu7\.virtualenvs\microblog-PZe2x5ce\lib\site-packages\flask\_compat.py", line 35, in reraise
    raise value
  File "C:\Users\asu7\.virtualenvs\microblog-PZe2x5ce\lib\site-packages\flask\app.py", line 1813, in full_dispatch_request
    rv = self.dispatch_request()
  File "C:\Users\asu7\.virtualenvs\microblog-PZe2x5ce\lib\site-packages\flask\app.py", line 1799, in dispatch_request
    return self.view_functions[rule.endpoint](**req.view_args)
  File "C:\Users\asu7\.virtualenvs\microblog-PZe2x5ce\lib\site-packages\flask_login\utils.py", line 261, in decorated_view
    return func(*args, **kwargs)
  File "C:\Users\asu7\Desktop\Py\apps\microblog\app\main\routes.py", line 118, in search
    posts, total    = Post.search(g.search_form.q.data, page, current_app.config['POST_PER_PAGE'])
  File "C:\Users\asu7\Desktop\Py\apps\microblog\app\models.py", line 21, in search
    ids, total = query_index(cls.__tablename__, expression, page, per_page)
  File "C:\Users\asu7\Desktop\Py\apps\microblog\app\search.py", line 21, in query_index
    'from': (page - 1) * per_page, 'size': per_page})
  File "C:\Users\asu7\.virtualenvs\microblog-PZe2x5ce\lib\site-packages\elasticsearch\client\utils.py", line 76, in _wrapped
    return func(*args, params=params, **kwargs)
  File "C:\Users\asu7\.virtualenvs\microblog-PZe2x5ce\lib\site-packages\elasticsearch\client\__init__.py", line 660, in search
    doc_type, '_search'), params=params, body=body)
  File "C:\Users\asu7\.virtualenvs\microblog-PZe2x5ce\lib\site-packages\elasticsearch\transport.py", line 318, in perform_request
    status, headers_response, data = connection.perform_request(method, url, params, body, headers=headers, ignore=ignore, timeout=timeout)
  File "C:\Users\asu7\.virtualenvs\microblog-PZe2x5ce\lib\site-packages\elasticsearch\connection\http_urllib3.py", line 186, in perform_request
    self._raise_error(response.status, raw_data)
  File "C:\Users\asu7\.virtualenvs\microblog-PZe2x5ce\lib\site-packages\elasticsearch\connection\base.py", line 125, in _raise_error
    raise HTTP_EXCEPTIONS.get(status_code, TransportError)(status_code, error_message, additional_info)
elasticsearch.exceptions.NotFoundError: NotFoundError(404, 'index_not_found_exception', 'no such index')
2019-01-17 08:08:53,989 INFO: Microblog startup [in C:\Users\asu7\Desktop\Py\apps\microblog\app\__init__.py:114]
2019-01-17 08:19:59,334 INFO: Microblog startup [in C:\Users\asu7\Desktop\Py\apps\microblog\app\__init__.py:114]
2019-01-17 08:20:54,422 INFO: Microblog startup [in C:\Users\asu7\Desktop\Py\apps\microblog\app\__init__.py:114]
2019-01-17 08:25:21,118 INFO: Microblog startup [in C:\Users\asu7\Desktop\Py\apps\microblog\app\__init__.py:114]
2019-01-17 08:29:08,439 INFO: Microblog startup [in C:\Users\asu7\Desktop\Py\apps\microblog\app\__init__.py:114]
2019-01-17 08:29:26,539 ERROR: Exception on /search [GET] [in C:\Users\asu7\.virtualenvs\microblog-PZe2x5ce\lib\site-packages\flask\app.py:1761]
Traceback (most recent call last):
  File "C:\Users\asu7\.virtualenvs\microblog-PZe2x5ce\lib\site-packages\flask\app.py", line 2292, in wsgi_app
    response = self.full_dispatch_request()
  File "C:\Users\asu7\.virtualenvs\microblog-PZe2x5ce\lib\site-packages\flask\app.py", line 1815, in full_dispatch_request
    rv = self.handle_user_exception(e)
  File "C:\Users\asu7\.virtualenvs\microblog-PZe2x5ce\lib\site-packages\flask\app.py", line 1718, in handle_user_exception
    reraise(exc_type, exc_value, tb)
  File "C:\Users\asu7\.virtualenvs\microblog-PZe2x5ce\lib\site-packages\flask\_compat.py", line 35, in reraise
    raise value
  File "C:\Users\asu7\.virtualenvs\microblog-PZe2x5ce\lib\site-packages\flask\app.py", line 1813, in full_dispatch_request
    rv = self.dispatch_request()
  File "C:\Users\asu7\.virtualenvs\microblog-PZe2x5ce\lib\site-packages\flask\app.py", line 1799, in dispatch_request
    return self.view_functions[rule.endpoint](**req.view_args)
  File "C:\Users\asu7\.virtualenvs\microblog-PZe2x5ce\lib\site-packages\flask_login\utils.py", line 261, in decorated_view
    return func(*args, **kwargs)
  File "C:\Users\asu7\Desktop\Py\apps\microblog\app\main\routes.py", line 118, in search
    posts, total    = Post.search(g.search_form.q.data, page, current_app.config['POST_PER_PAGE'])
  File "C:\Users\asu7\Desktop\Py\apps\microblog\app\models.py", line 21, in search
    ids, total = query_index(cls.__tablename__, expression, page, per_page)
  File "C:\Users\asu7\Desktop\Py\apps\microblog\app\search.py", line 21, in query_index
    'from': (page - 1) * per_page, 'size': per_page})
  File "C:\Users\asu7\.virtualenvs\microblog-PZe2x5ce\lib\site-packages\elasticsearch\client\utils.py", line 76, in _wrapped
    return func(*args, params=params, **kwargs)
  File "C:\Users\asu7\.virtualenvs\microblog-PZe2x5ce\lib\site-packages\elasticsearch\client\__init__.py", line 660, in search
    doc_type, '_search'), params=params, body=body)
  File "C:\Users\asu7\.virtualenvs\microblog-PZe2x5ce\lib\site-packages\elasticsearch\transport.py", line 318, in perform_request
    status, headers_response, data = connection.perform_request(method, url, params, body, headers=headers, ignore=ignore, timeout=timeout)
  File "C:\Users\asu7\.virtualenvs\microblog-PZe2x5ce\lib\site-packages\elasticsearch\connection\http_urllib3.py", line 186, in perform_request
    self._raise_error(response.status, raw_data)
  File "C:\Users\asu7\.virtualenvs\microblog-PZe2x5ce\lib\site-packages\elasticsearch\connection\base.py", line 125, in _raise_error
    raise HTTP_EXCEPTIONS.get(status_code, TransportError)(status_code, error_message, additional_info)
elasticsearch.exceptions.NotFoundError: NotFoundError(404, 'index_not_found_exception', 'no such index')
2019-01-17 08:34:02,836 INFO: Microblog startup [in C:\Users\asu7\Desktop\Py\apps\microblog\app\__init__.py:114]
2019-01-17 09:15:45,881 INFO: Microblog startup [in C:\Users\asu7\Desktop\Py\apps\microblog\app\__init__.py:114]
2019-01-17 09:23:54,134 INFO: Microblog startup [in C:\Users\asu7\Desktop\Py\apps\microblog\app\__init__.py:114]
2019-01-17 09:30:09,567 INFO: Microblog startup [in C:\Users\asu7\Desktop\Py\apps\microblog\app\__init__.py:114]
2019-01-17 09:34:07,809 INFO: Microblog startup [in C:\Users\asu7\Desktop\Py\apps\microblog\app\__init__.py:114]
2019-01-17 09:40:33,229 INFO: Microblog startup [in C:\Users\asu7\Desktop\Py\apps\microblog\app\__init__.py:114]
2019-01-17 10:03:20,403 INFO: Microblog startup [in C:\Users\asu7\Desktop\Py\apps\microblog\app\__init__.py:114]
2019-01-17 11:18:39,776 INFO: Microblog startup [in C:\Users\asu7\Desktop\Py\apps\microblog\app\__init__.py:114]
2019-01-17 15:00:11,940 INFO: Microblog startup [in C:\Users\asu7\Desktop\Py\apps\microblog\app\__init__.py:114]
2019-01-17 16:53:39,974 INFO: Microblog startup [in C:\Users\asu7\Desktop\Py\apps\microblog\app\__init__.py:114]
2019-01-17 16:58:02,854 INFO: Microblog startup [in C:\Users\asu7\Desktop\Py\apps\microblog\app\__init__.py:114]
2019-01-18 08:36:02,086 INFO: Microblog startup [in C:\Users\asu7\Desktop\Py\apps\microblog\app\__init__.py:114]
2019-01-18 08:37:27,512 INFO: Microblog startup [in C:\Users\asu7\Desktop\Py\apps\microblog\app\__init__.py:114]
2019-01-18 08:38:27,625 INFO: Microblog startup [in C:\Users\asu7\Desktop\Py\apps\microblog\app\__init__.py:114]
2019-01-18 08:47:50,049 INFO: Microblog startup [in C:\Users\asu7\Desktop\Py\apps\microblog\app\__init__.py:114]
2019-01-18 08:50:33,073 INFO: Microblog startup [in C:\Users\asu7\Desktop\Py\apps\microblog\app\__init__.py:114]
2019-01-18 08:51:43,562 INFO: Microblog startup [in C:\Users\asu7\Desktop\Py\apps\microblog\app\__init__.py:114]
2019-01-18 08:59:58,126 INFO: Microblog startup [in C:\Users\asu7\Desktop\Py\apps\microblog\app\__init__.py:114]
2019-01-18 09:01:03,431 INFO: Microblog startup [in C:\Users\asu7\Desktop\Py\apps\microblog\app\__init__.py:114]
2019-01-18 09:01:45,986 INFO: Microblog startup [in C:\Users\asu7\Desktop\Py\apps\microblog\app\__init__.py:114]
2019-01-18 09:02:18,018 INFO: Microblog startup [in C:\Users\asu7\Desktop\Py\apps\microblog\app\__init__.py:114]
2019-01-18 09:03:02,535 INFO: Microblog startup [in C:\Users\asu7\Desktop\Py\apps\microblog\app\__init__.py:114]
2019-01-18 09:03:19,948 INFO: Microblog startup [in C:\Users\asu7\Desktop\Py\apps\microblog\app\__init__.py:114]
2019-01-18 09:03:54,750 INFO: Microblog startup [in C:\Users\asu7\Desktop\Py\apps\microblog\app\__init__.py:114]
2019-01-18 09:05:53,885 INFO: Microblog startup [in C:\Users\asu7\Desktop\Py\apps\microblog\app\__init__.py:114]
2019-01-18 09:06:34,363 INFO: Microblog startup [in C:\Users\asu7\Desktop\Py\apps\microblog\app\__init__.py:114]
2019-01-18 09:07:27,387 INFO: Microblog startup [in C:\Users\asu7\Desktop\Py\apps\microblog\app\__init__.py:114]
2019-01-18 09:08:58,862 INFO: Microblog startup [in C:\Users\asu7\Desktop\Py\apps\microblog\app\__init__.py:114]
2019-01-18 09:09:22,628 INFO: Microblog startup [in C:\Users\asu7\Desktop\Py\apps\microblog\app\__init__.py:114]
2019-01-18 09:09:51,925 INFO: Microblog startup [in C:\Users\asu7\Desktop\Py\apps\microblog\app\__init__.py:114]
2019-01-18 09:10:54,744 INFO: Microblog startup [in C:\Users\asu7\Desktop\Py\apps\microblog\app\__init__.py:114]
2019-01-18 09:11:56,750 INFO: Microblog startup [in C:\Users\asu7\Desktop\Py\apps\microblog\app\__init__.py:114]
2019-01-18 09:12:22,771 INFO: Microblog startup [in C:\Users\asu7\Desktop\Py\apps\microblog\app\__init__.py:114]
2019-01-18 09:13:32,467 INFO: Microblog startup [in C:\Users\asu7\Desktop\Py\apps\microblog\app\__init__.py:114]
2019-01-18 09:16:13,627 INFO: Microblog startup [in C:\Users\asu7\Desktop\Py\apps\microblog\app\__init__.py:114]
2019-01-18 09:17:30,027 INFO: Microblog startup [in C:\Users\asu7\Desktop\Py\apps\microblog\app\__init__.py:114]
2019-01-18 09:18:05,986 INFO: Microblog startup [in C:\Users\asu7\Desktop\Py\apps\microblog\app\__init__.py:114]
2019-01-18 09:18:32,929 INFO: Microblog startup [in C:\Users\asu7\Desktop\Py\apps\microblog\app\__init__.py:114]
2019-01-18 09:18:54,961 INFO: Microblog startup [in C:\Users\asu7\Desktop\Py\apps\microblog\app\__init__.py:114]
2019-01-18 09:20:45,379 INFO: Microblog startup [in C:\Users\asu7\Desktop\Py\apps\microblog\app\__init__.py:114]
2019-01-18 09:21:00,516 INFO: Microblog startup [in C:\Users\asu7\Desktop\Py\apps\microblog\app\__init__.py:114]
2019-01-18 09:24:43,892 INFO: Microblog startup [in C:\Users\asu7\Desktop\Py\apps\microblog\app\__init__.py:114]
2019-01-18 09:25:17,639 INFO: Microblog startup [in C:\Users\asu7\Desktop\Py\apps\microblog\app\__init__.py:114]
2019-01-18 09:55:42,713 INFO: Microblog startup [in C:\Users\asu7\Desktop\Py\apps\microblog\app\__init__.py:114]
2019-01-18 09:57:18,317 INFO: Microblog startup [in C:\Users\asu7\Desktop\Py\apps\microblog\app\__init__.py:114]
2019-01-18 10:34:59,446 INFO: Microblog startup [in C:\Users\asu7\Desktop\Py\apps\microblog\app\__init__.py:114]
2019-01-18 10:59:39,406 INFO: Microblog startup [in C:\Users\asu7\Desktop\Py\apps\microblog\app\__init__.py:114]
2019-01-18 10:59:47,684 ERROR: Exception on /messages [GET] [in C:\Users\asu7\.virtualenvs\microblog-PZe2x5ce\lib\site-packages\flask\app.py:1761]
Traceback (most recent call last):
  File "C:\Users\asu7\.virtualenvs\microblog-PZe2x5ce\lib\site-packages\flask\app.py", line 2292, in wsgi_app
    response = self.full_dispatch_request()
  File "C:\Users\asu7\.virtualenvs\microblog-PZe2x5ce\lib\site-packages\flask\app.py", line 1815, in full_dispatch_request
    rv = self.handle_user_exception(e)
  File "C:\Users\asu7\.virtualenvs\microblog-PZe2x5ce\lib\site-packages\flask\app.py", line 1718, in handle_user_exception
    reraise(exc_type, exc_value, tb)
  File "C:\Users\asu7\.virtualenvs\microblog-PZe2x5ce\lib\site-packages\flask\_compat.py", line 35, in reraise
    raise value
  File "C:\Users\asu7\.virtualenvs\microblog-PZe2x5ce\lib\site-packages\flask\app.py", line 1813, in full_dispatch_request
    rv = self.dispatch_request()
  File "C:\Users\asu7\.virtualenvs\microblog-PZe2x5ce\lib\site-packages\flask\app.py", line 1799, in dispatch_request
    return self.view_functions[rule.endpoint](**req.view_args)
  File "C:\Users\asu7\.virtualenvs\microblog-PZe2x5ce\lib\site-packages\flask_login\utils.py", line 261, in decorated_view
    return func(*args, **kwargs)
  File "C:\Users\asu7\Desktop\Py\apps\microblog\app\main\routes.py", line 149, in messages
    messages    = current_user.messages_recieved.order_by(
  File "C:\Users\asu7\.virtualenvs\microblog-PZe2x5ce\lib\site-packages\werkzeug\local.py", line 347, in __getattr__
    return getattr(self._get_current_object(), name)
AttributeError: 'User' object has no attribute 'messages_recieved'
2019-01-18 11:01:15,421 ERROR: Exception on /messages [GET] [in C:\Users\asu7\.virtualenvs\microblog-PZe2x5ce\lib\site-packages\flask\app.py:1761]
Traceback (most recent call last):
  File "C:\Users\asu7\.virtualenvs\microblog-PZe2x5ce\lib\site-packages\flask\app.py", line 2292, in wsgi_app
    response = self.full_dispatch_request()
  File "C:\Users\asu7\.virtualenvs\microblog-PZe2x5ce\lib\site-packages\flask\app.py", line 1815, in full_dispatch_request
    rv = self.handle_user_exception(e)
  File "C:\Users\asu7\.virtualenvs\microblog-PZe2x5ce\lib\site-packages\flask\app.py", line 1718, in handle_user_exception
    reraise(exc_type, exc_value, tb)
  File "C:\Users\asu7\.virtualenvs\microblog-PZe2x5ce\lib\site-packages\flask\_compat.py", line 35, in reraise
    raise value
  File "C:\Users\asu7\.virtualenvs\microblog-PZe2x5ce\lib\site-packages\flask\app.py", line 1813, in full_dispatch_request
    rv = self.dispatch_request()
  File "C:\Users\asu7\.virtualenvs\microblog-PZe2x5ce\lib\site-packages\flask\app.py", line 1799, in dispatch_request
    return self.view_functions[rule.endpoint](**req.view_args)
  File "C:\Users\asu7\.virtualenvs\microblog-PZe2x5ce\lib\site-packages\flask_login\utils.py", line 261, in decorated_view
    return func(*args, **kwargs)
  File "C:\Users\asu7\Desktop\Py\apps\microblog\app\main\routes.py", line 149, in messages
    messages    = current_user.messages_recieved.order_by(
  File "C:\Users\asu7\.virtualenvs\microblog-PZe2x5ce\lib\site-packages\werkzeug\local.py", line 347, in __getattr__
    return getattr(self._get_current_object(), name)
AttributeError: 'User' object has no attribute 'messages_recieved'
2019-01-18 11:05:07,083 INFO: Microblog startup [in C:\Users\asu7\Desktop\Py\apps\microblog\app\__init__.py:114]
2019-01-18 11:37:28,302 INFO: Microblog startup [in C:\Users\asu7\Desktop\Py\apps\microblog\app\__init__.py:114]
2019-01-18 11:48:51,289 INFO: Microblog startup [in C:\Users\asu7\Desktop\Py\apps\microblog\app\__init__.py:114]
2019-01-18 11:51:38,879 INFO: Microblog startup [in C:\Users\asu7\Desktop\Py\apps\microblog\app\__init__.py:114]
2019-01-18 13:32:42,079 INFO: Microblog startup [in C:\Users\asu7\Desktop\Py\apps\microblog\app\__init__.py:114]
2019-01-18 13:32:56,789 INFO: Microblog startup [in C:\Users\asu7\Desktop\Py\apps\microblog\app\__init__.py:114]
2019-01-18 13:33:05,095 INFO: Microblog startup [in C:\Users\asu7\Desktop\Py\apps\microblog\app\__init__.py:114]
2019-01-18 14:06:20,559 INFO: Microblog startup [in C:\Users\asu7\Desktop\Py\apps\microblog\app\__init__.py:114]
